Workbook

Sheet اعتماد الشهادات 1
A1: The main file of the International Board’s certificates for trainees and vocational qualification
A2: اسم المتدرب | B2: الرقم المتسلسل المعتمد | C2: الرمز | D2: رقم الاعتماد | E2: نوع الوثيقة | F2: تاريخ الاعتماد | G2: اسم المدرب | H2: الحنسية | I2: الحصول على الوثيقة ورقيا | J2: ملاحظات
A3: Academy of Scientific Professionalism for Training and Rehabilitation | B3: IB124 | C3: 73 | D3: ='اعتماد الشهادات 1'!$B3&'اعتماد الشهادات 1'!$C3 -> IB12473 | E3: accreditation center | F3: 44594 | G3: Maen Al Shammari | H3: Libya | I3: YAS
A4: Wiam Ali Kshad | B4: IB125 | C4: 80 | D4: ='اعتماد الشهادات 1'!$B4&'اعتماد الشهادات 1'!$C4 -> IB12580 | E4: Training of Trainers (TOT) | F4: 44606 | G4: Maen Al Shammari | H4: Libya | I4: YAS
A5: Awatif Othman Alkuwafl | B5: IB126 | C5: 65 | D5: ='اعتماد الشهادات 1'!$B5&'اعتماد الشهادات 1'!$C5 -> IB12665 | E5: Training of Trainers (TOT) | F5: 44606 | G5: Maen Al Shammari | H5: Libya | I5: YAS
A6: Basma Mohamad Alsharef | B6: IB127 | C6: 44 | D6: ='اعتماد الشهادات 1'!$B6&'اعتماد الشهادات 1'!$C6 -> IB12744 | E6: Training of Trainers (TOT) | F6: 44606 | G6: Maen Al Shammari | H6: Libya | I6: YAS
A7: Fatima abdoulha boderbala mayof | B7: IB128 | C7: 60 | D7: ='اعتماد الشهادات 1'!$B7&'اعتماد الشهادات 1'!$C7 -> IB12860 | E7: Training of Trainers (TOT) | F7: 44606 | G7: Maen Al Shammari | H7: Libya | I7: YAS
A8: SALMA ABDULKARIM ALTAWATI ALSANAKIA | B8: IB129 | C8: 53 | D8: ='اعتماد الشهادات 1'!$B8&'اعتماد الشهادات 1'!$C8 -> IB12953 | E8: Training of Trainers (TOT) | F8: 44606 | G8: Maen Al Shammari | H8: Libya | I8: YAS
A9: Fatima Ali Faraj Halash | B9: IB130 | C9: 39 | D9: ='اعتماد الشهادات 1'!$B9&'اعتماد الشهادات 1'!$C9 -> IB13039 | E9: Training of Trainers (TOT) | F9: 44606 | G9: Maen Al Shammari | H9: Libya | I9: YAS
A10: Suhair mousa shehadeh | B10: IB131 | C10: 19 | D10: ='اعتماد الشهادات 1'!$B10&'اعتماد الشهادات 1'!$C10 -> IB13119 | E10: Training of Trainers (TOT) | F10: 44606 | G10: Maen Al Shammari | H10: Libya | I10: YAS
A11: Sherefa Mohammed Faraj Barka | B11: IB132 | C11: 31 | D11: ='اعتماد الشهادات 1'!$B11&'اعتماد الشهادات 1'!$C11 -> IB13231 | E11: Training of Trainers (TOT) | F11: 44606 | G11: Maen Al Shammari | H11: Libya | I11: YAS
A12: Jamal Sabry Anfous | B12: IB133 | C12: 18 | D12: ='اعتماد الشهادات 1'!$B12&'اعتماد الشهادات 1'!$C12 -> IB13318 | E12: Training of Trainers (TOT) | F12: 44606 | G12: Maen Al Shammari | H12: Syria | I12: YAS
A13: Fathia AliMohammed Alhoni | B13: IB134 | C13: 56 | D13: ='اعتماد الشهادات 1'!$B13&'اعتماد الشهادات 1'!$C13 -> IB13456 | E13: Training of Trainers (TOT) | F13: 44606 | G13: Maen Al Shammari | H13: Libya | I13: YAS
A14: Mohamed hassan Zaki gad abou elnasr | B14: IB135 | C14: 91 | D14: ='اعتماد الشهادات 1'!$B14&'اعتماد الشهادات 1'!$C14 -> IB13591 | E14: Training of Trainers (TOT) | F14: 44606 | G14: Maen Al Shammari | H14: Egption | I14: YAS
... A22: Iman Mohamed busnena | B22: IB143 | C22: 34 | D22: ='اعتماد الشهادات 1'!$B22&'اعتماد الشهادات 1'!$C22 -> IB14334 | E22: Training of Trainers (TOT) | F22: 44637 | G22: Maen Al Shammari | H22: Libya | I22: YAS
A23: Mohammed Amou Hawbe | B23: IB144 | C23: 23 | D23: ='اعتماد الشهادات 1'!$B23&'اعتماد الشهادات 1'!$C23 -> IB14423 | E23: Training of Trainers (TOT) | F23: 44637 | G23: Maen Al Shammari | H23: Mauritania | I23: YAS | J23: الرقم الصحيح IB14323
A24: ALI AHMED MOHAMMED | B24: IB145 | C24: 15 | D24: ='اعتماد الشهادات 1'!$B24&'اعتماد الشهادات 1'!$C24 -> IB14515 | E24: Training of Trainers (TOT) | F24: 44637 | G24: Maen Al Shammari | H24: Libya | I24: YAS
A25: Asma El Hadi Ahmed Salem | B25: IB146 | C25: 54 | D25: ='اعتماد الشهادات 1'!$B25&'اعتماد الشهادات 1'!$C25 -> IB14654 | E25: Training of Trainers (TOT) | F25: 44637 | G25: Maen Al Shammari | H25: Libya | I25: YAS
A26: Zaineb Muhsen Aldulaa | B26: IB147 | C26: 31 | D26: ='اعتماد الشهادات 1'!$B26&'اعتماد الشهادات 1'!$C26 -> IB14731 | E26: Training of Trainers (TOT) | F26: 44637 | G26: Maen Al Shammari | H26: Libya | I26: YAS
A27: Muna Al Hashmi Saeid Al Sagheer | B27: IB148 | C27: 34 | D27: ='اعتماد الشهادات 1'!$B27&'اعتماد الشهادات 1'!$C27 -> IB14834 | E27: Training of Trainers (TOT) | F27: 44637 | G27: Maen Al Shammari | H27: Libya | I27: YAS
A28: KAHDIGAH GABRIEL ALTUWATI ALSHNNAKIA | B28: IB149 | C28: 87 | D28: ='اعتماد الشهادات 1'!$B28&'اعتماد الشهادات 1'!$C28 -> IB14987 | E28: Training of Trainers (TOT) | F28: 44637 | G28: Maen Al Shammari | H28: Libya | I28: YAS
A29: Hiam Ali Elrabty | B29: IB150 | C29: 24 | D29: ='اعتماد الشهادات 1'!$B29&'اعتماد الشهادات 1'!$C29 -> IB15024 | E29: Training of Trainers (TOT) | F29: 44637 | G29: Maen Al Shammari | H29: Libya | I29: YAS
A30: Mohamed Mohamed Mahmoud | B30: IB151 | C30: 92 | D30: ='اعتماد الشهادات 1'!$B30&'اعتماد الشهادات 1'!$C30 -> IB15192 | E30: Training of Trainers (TOT) | F30: 44637 | G30: Maen Al Shammari | H30: Mauritania | I30: YAS
A31: Aisha Abubakar Emhemd Altaher | B31: IB152 | C31: 65 | D31: ='اعتماد الشهادات 1'!$B31&'اعتماد الشهادات 1'!$C31 -> IB15265 | E31: Training of Trainers (TOT) | F31: 44637 | G31: Maen Al Shammari | H31: Libya | I31: YAS
A32: Mona Mosa Alawamy | B32: IB153 | C32: 11 | D32: ='اعتماد الشهادات 1'!$B32&'اعتماد الشهادات 1'!$C32 -> IB15311 | E32: Training of Trainers (TOT) | F32: 44637 | G32: Maen Al Shammari | H32: Libya | I32: YAS
A33: KALTHOUM ALAMEER ABDULLAH | B33: IB154 | C33: 22 | D33: ='اعتماد الشهادات 1'!$B33&'اعتماد الشهادات 1'!$C33 -> IB15422 | E33: Training of Trainers (TOT) | F33: 44606 | G33: Maen Al Shammari | H33: Libya | I33: YAS
A34: Ali Mohammad Hammoud | B34: IB155 | C34: 78 | D34: ='اعتماد الشهادات 1'!$B34&'اعتماد الشهادات 1'!$C34 -> IB15578 | E34: Diploma in Simultaneous Translation | F34: 13/1/2025 | G34: Ahmad Alkoud | H34: Syria
A35: Hamlinha Daw Ali | B35: IB156 | C35: 83 | D35: ='اعتماد الشهادات 1'!$B35&'اعتماد الشهادات 1'!$C35 -> IB15683 | E35: Training of Trainers (TOT) | F35: 21/14/2022 | G35: Maen Al Shammari | H35: Libya | I35: YAS
A36: Osama Hassouni. Al Hariri | B36: IB157 | C36: 17 | D36: ='اعتماد الشهادات 1'!$B36&'اعتماد الشهادات 1'!$C36 -> IB15717 | E36: Training of Trainers (TOT) | F36: 21/14/2022 | G36: Maen Al Shammari | H36: Syria | I36: YAS
A37: Ramiz Abdulgani Rashed | B37: IB158 | C37: 43 | D37: ='اعتماد الشهادات 1'!$B37&'اعتماد الشهادات 1'!$C37 -> IB15843 | E37: Training of Trainers (TOT) | F37: 21/14/2022 | G37: Maen Al Shammari | H37: Syria | I37: YAS
A38: Khaledajumasta | B38: IB159 | C38: 63 | D38: ='اعتماد الشهادات 1'!$B38&'اعتماد الشهادات 1'!$C38 -> IB15963 | E38: Training of Trainers (TOT) | F38: 21/14/2022 | G38: Maen Al Shammari | H38: Syria | I38: YAS
A39: Nada Atalaa Alkatayb | B39: IB160 | C39: 48 | D39: ='اعتماد الشهادات 1'!$B39&'اعتماد الشهادات 1'!$C39 -> IB16048 | E39: Training of Trainers (TOT) | F39: 21/14/2022 | G39: Maen Al Shammari | H39: Syria | I39: YAS
A40: Rola Atallah Alkhateeb | B40: IB161 | C40: 47 | D40: ='اعتماد الشهادات 1'!$B40&'اعتماد الشهادات 1'!$C40 -> IB16147 | E40: Training of Trainers (TOT) | F40: 21/14/2022 | G40: Maen Al Shammari | H40: Syria | I40: YAS
A41: HOSSAM SAAD ALSAYED SELIM | B41: IB162 | C41: 66 | D41: ='اعتماد الشهادات 1'!$B41&'اعتماد الشهادات 1'!$C41 -> IB16266 | E41: Training of Trainers (TOT) | F41: 21/14/2022 | G41: Maen Al Shammari | H41: Syria | I41: YAS
A42: Abeer Radi Almasalmeh | B42: IB163 | C42: 62 | D42: ='اعتماد الشهادات 1'!$B42&'اعتماد الشهادات 1'!$C42 -> IB16362 | E42: Training of Trainers (TOT) | F42: 21/14/2022 | G42: Maen Al Shammari | H42: Syria | I42: YAS
A43: Haifa Mamdoh Rahed | B43: IB164 | C43: 31 | D43: ='اعتماد الشهادات 1'!$B43&'اعتماد الشهادات 1'!$C43 -> IB16431 | E43: Training of Trainers (TOT) | F43: 21/14/2022 | G43: Maen Al Shammari | H43: Syria | I43: YAS
A44: Rola Ahmad Jaafreh | B44: IB165 | C44: 37 | D44: ='اعتماد الشهادات 1'!$B44&'اعتماد الشهادات 1'!$C44 -> IB16537 | E44: Medical diploma skills | F44: 21/14/2022 | G44: Alaa Ghalib | H44: Palestine | I44: YAS
A45: IBRAHIM MOHAMMAD AL SHEBLAK | B45: IB166 | C45: 90 | D45: ='اعتماد الشهادات 1'!$B45&'اعتماد الشهادات 1'!$C45 -> IB16690 | E45: Training of Trainers (TOT) | F45: 21/14/2022 | G45: Ahmad Alkoud | H45: Syria | I45: YAS
A46: BOSHRA ABDULKARIM AL SHEBLAK | B46: IB167 | C46: 62 | D46: ='اعتماد الشهادات 1'!$B46&'اعتماد الشهادات 1'!$C46 -> IB16762 | E46: Training of Trainers (TOT) | F46: 21/14/2022 | G46: Ahmad Alkoud | H46: Syria | I46: YAS
... A61: Ahmed Issa Al-Wadi | B61: IB182 | C61: 79 | D61: ='اعتماد الشهادات 1'!$B61&'اعتماد الشهادات 1'!$C61 -> IB18279 | E61: Authorized Agent | F61: 21/14/2022 | G61: Ahmad Alkoud | H61: Syria | I61: YAS
...

Sheet اعتماد 2
A1: WASSIM SOPEH SOPEH | B1: FATIMA ABD ALATIF ALMOHBANI | C1: IB20221 | D1: 4 | E1: ='[1]اعتماد الشهادات 2'!$B1&'[1]اعتماد الشهادات 2'!$C1 -> #REF! | F1: Nursing And First Aid Skills | G1: 45575 | H1: Bashir Al Kilani | I1: سوري | J1: لا
A2: MAHMOUD OMAR HOMIDE | B2: SALMAN RAMDAN ALSALEEM | C2: IB20222 | D2: 4 | E2: IB199903 | F2: Advanced Diploma In Accounting | G2: 45596 | H2: Bashir Al Kilani | I2: سوري | J2: لا
A3: MAHMOUD OMAR HOMIDE | B3: MOHAMMED HAZEM ZOHER SHAHEEN | C3: IB20223 | D3: 4 | E3: IB199912 | F3: Advanced Diploma In Accounting | G3: 45590 | H3: Bashir Al Kilani | I3: سوري | J3: لا
A4: REEM ABDULGHANI ALSHBLI | B4: MOHAMAD SOLIMAN FERAS ALKHDER | C4: IB20224 | D4: 4 | E4: IB199925 | F4: Mobile Maintenance Technician | G4: 45603 | H4: Bashir Al Kilani | I4: سوري | J4: لا
A5: RAWAN ALI RASHED | B5: SAJED FERAS ALKHDER | C5: IB20225 | D5: 5 | E5: IB199932 | F5: Mobile Maintenance Technician | G5: 45603 | H5: Bashir Al Kilani | I5: سوري | J5: لا
A6: RADWAN BASAAM ALABRASH | B6: SANDY MOHAMAD ALSAYED | C6: IB20226 | D6: 3 | E6: IB199943 | F6: TRAINING OF TRAINERS | G6: 45607 | H6: Bashir Al Kilani | I6: سوري | J6: لا
A7: HADEEL ALSAHSAH EZZO | B7: GHAZAL SAMEER ALSADAT | C7: IB20227 | D7: 4 | E7: IB199954 | F7: TRAINING OF TRAINERS | G7: 45607 | H7: Bashir Al Kilani | I7: سوري | J7: لا
A8: FARAH MOHAMAD ALNABLSE | B8: MUSTAPHA KENAN ALHAYEK | C8: IB20228 | D8: 4 | E8: IB199964 | F8: TRAINING OF TRAINERS | G8: 45607 | H8: Bashir Al Kilani | I8: سوري | J8: لا
A9: MOUSTAFA ADNAN AIHAKIM | B9: AHMAD HUSSEIN JABR | C9: IB20229 | D9: 4 | E9: IB199973 | F9: TRAINING OF TRAINERS | G9: 45607 | H9: Bashir Al Kilani | I9: سوري | J9: لا
A10: MUHAMMAD ADNAN ALHAKEEM | B10: MONTAHA IBRAHIM AL AHMAD | C10: IB20230 | D10: 2 | E10: IB199982 | F10: TRAINING OF TRAINERS | G10: 45607 | H10: Bashir Al Kilani | I10: سوري | J10: لا
A11: AMEEN ASAD ALTAYASNEH | B11: REHAB HUSSEIN RESHEE | C11: IB20231 | D11: 3 | E11: IB199995 | F11: TRAINING OF TRAINERS | G11: 45607 | H11: Bashir Al Kilani | I11: سوري | J11: لا
A12: MOHAMMAD HOSSIEN ABOJABAL | B12: HADEEL ALSAHSAH EZZO | C12: IB20232 | D12: 4 | E12: IB200004 | F12: TRAINING OF TRAINERS | G12: 45607 | H12: Bashir Al Kilani | I12: سوري | J12: لا
A13: NIZAR MESAAB ABUALSEL | B13: SHAM KENAN ALHAYEK | C13: IB20233 | D13: 3 | E13: IB200015 | F13: TRAINING OF TRAINERS | G13: 45607 | H13: Bashir Al Kilani | I13: سوري | J13: لا
... A32: MAREA ADNAN ALDAHR | B32: HASAN AHMAD YOUNES | C32: IB20252 | D32: 2 | E32: IB200202 | F32: Office Programs | G32: 45614 | H32: Bashir Al Kilani | I32: سوري | J32: لا
A33: MAJD ALDEEN AZAM ALMUHAMMED | B33: FATIMA MOHAMMED ROHI QURAIN | C33: IB20255 | D33: 4 | E33: IB202554 | F33: Emotional Intelligence | G33: 45610 | H33: Bashir Al Kilani
A34: KHADER HUSSEIN SHEIKH DAHER | B34: YAMAM MUHSSEN ASAD | C34: IB20256 | D34: 2 | E34: IB202562 | F34: Medical Translation & Medical Content Writing | G34: 45532 | H34: Bashir Al Kilani
A35: AHMAD ABDULWAHED ALSAEED | B35: REEM SAMIR JALHOUM | C35: IB20257 | D35: 2 | E35: IB202572 | F35: Graphic Design | G35: 45613 | H35: Bashir Al Kilani
A36: SULEIMAN AHMED ALSAREM | B36: ZEINA SAMI ABOUD | C36: IB20258 | D36: 5 | E36: IB202585 | F36: Graphic Design | G36: 45613 | H36: Bashir Al Kilani
A37: MOHAMED YOUSEF SHABALOUT | B37: NOURA MONI SALLOUM | C37: IB20259 | D37: 4 | E37: IB202594 | F37: Graphic Design | G37: 45613 | H37: Bashir Al Kilani
A38: ABDULRAHIM RASLAN ALJAMOUS
A39: MOSTAFA AMMAR YAHIA
A40: NOURSHAN MOHMAD LOOSH
A41: IBRAHEM MOFAK MLHEM
A42: MUSTAFA TAREK HAJ FATTOUH
A43: ALI AHMAD OTHMAN
A44: AYMAN MOHAMMED AMER KRENBEH
A45: SARA IBRAHEEM ALHERABALI
A46: MOHAMMAD SALIM DIAB ALHIRBAWII
A47: ABDALRAHMAN MOHAMMED KHIR HAJ ALI
A48: ANAS DIAB ALHASHASH
A49: HAJAR FARID ALSALEH
... A263: HASAN AHMAD YOUNES

Sheet اعتماد المراكز
A1: اسم المركز | B1: رقم اعتماد المركز | C1: اسم المسؤول / المشرف عن المركز | D1: مقر المركز / البلد | E1: العنوان بتفصيل | F1: ايميل المركز "البريد الالكتروني" | G1: رقم تواصل | H1: تاريخ اعتماد المركز | I1: تاريخ انتهاء الاعتماد
A2: مركز سواعد | B2: IB28183 | C2: بشير مصطفى كيلاني | D2: سوريا | E2: حمص - الساعة الجديدة - فرب متحف بناء خلدون | F2: center.swaed@gmail.com | G2: 936353677 | H2: 44773 | I2: 44924
A3: مركز ابداع للتنمية والتدريب الاحترافي | B3: IB28263 | C3: ربى عبد الكريم الاسعد | D3: سوريا | E3: السويداء - طريق قنوات - شمال دوار الزنبقة بناء سوليه2 | F3: ebdaayouth1@gmail.com | G3: 937859998 | H3: 44772 | I3: 44924
A4: مركز نبض التنموي | B4: IB28089 | C4: عمار رمضان | D4: سوريا | E4: حماه - شارع المرابط مجمع الخاني طابق الثالث | F4: dr.ammar-alramadan@hotmail.com | G4: 940300690 | H4: 44775 | I4: 44925
A5: اعمالكم للخدمات اللوجستية | B5: IB35751 | C5: طلال موسى محمد مشاقبة | D5: الأردن | E5: المفرق - شارع جرش قرب بنك الاتحاد | G5: 792843920 | H5: 44784 | I5: 44925
A6: أكاديمية أليسار التعليمية | B6: IB37125 | C6: اليسار نوف | D6: سوريا | E6: دمشق المزة 86 شارع البيت الطويل شارع 16 | F6: alisarnayouftrainer@gmail.com | G6: 992367778 | H6: 44786 | I6: 44925
A7: اكاديمية ابن حزم للتدريب والتعليم والتنمية البشرية | B7: IB41059 | C7: احمد حسين العبدالله | D7: سوريا | E7: دير زور- مدينة هحين - شارع الثانوية بناء عبد العزيزي الغفوري | F7: IbnHazmAcademy@gmail.com | G7: 993539611 | H7: 44810 | I7: 44925
A8: فريق الولاء للتدريب والاستشارات | B8: ='اعتماد الشهادات 1'!$B8&'اعتماد الشهادات 1'!$C8 -> IB12953 | C8: ولاء محمد عدنان الصالحاني | D8: سوريا | F8: WalaaAlsalhani11@gmail.com | H8: 44855 | I8: 44925
B9: ='اعتماد الشهادات 1'!$B9&'اعتماد الشهادات 1'!$C9 -> IB13039 | E9: idea36630@gmail.com | F9: فكرة
A10: Helioplice center | B10: ='اعتماد الشهادات 1'!$B10&'اعتماد الشهادات 1'!$C10 -> IB13119 | G10: 963969047606
B11: ='اعتماد الشهادات 1'!$B11&'اعتماد الشهادات 1'!$C11 -> IB13231
